# Python Exception Handling

Exception handling is an important aspect of writing robust and reliable Python code. In this guide, we will explore how to handle exceptions in Python.

## What are Exceptions?

Exceptions are events that occur during the execution of a program that disrupt the normal flow of the program. When an exception occurs, the program execution is immediately halted, and the control is transferred to an exception handler.

## Handling Exceptions with Try/Except Blocks

In Python, exceptions are handled using `try` and `except` blocks. The `try` block contains the code that might raise an exception, and the `except` block is used to handle the exception.

Here's the basic syntax of a `try`/`except` block:

```python
try:
    # Code that might raise an exception
except ExceptionType:
    # Code to handle the exception
```

You can have multiple `except` blocks to handle different types of exceptions. The `ExceptionType` can be a specific exception class or a base class to handle multiple related exceptions.

## Example: Handling a ZeroDivisionError

Let's consider an example where we want to divide two numbers. However, if the denominator is zero, it will raise a `ZeroDivisionError`. We can handle this exception using a `try`/`except` block:

```python
try:
    numerator = 10
    denominator = 0
    result = numerator / denominator
    print("Result:", result)
except ZeroDivisionError:
    print("Error: Cannot divide by zero")
```

In this example, if the denominator is zero, the `ZeroDivisionError` exception will be raised, and the code inside the `except` block will be executed.

## Handling Multiple Exceptions

You can handle multiple exceptions by adding multiple `except` blocks. Each `except` block can handle a specific exception or a group of related exceptions.

```python
try:
    # Code that might raise exceptions
except ExceptionType1:
    # Code to handle ExceptionType1
except ExceptionType2:
    # Code to handle ExceptionType2
```

## Example: Handling Multiple Exceptions

```python
try:
    value = int(input("Enter a number: "))
    result = 10 / value
    print("Result:", result)
except ValueError:
    print("Error: Invalid input. Please enter a valid number.")
except ZeroDivisionError:
    print("Error: Cannot divide by zero.")
```

In this example, we handle both `ValueError` and `ZeroDivisionError` exceptions separately.

## The `finally` Block

The `finally` block is used to specify code that will be executed regardless of whether an exception occurred or not. It is often used to release resources or perform cleanup operations.

```python
try:
    # Code that might raise an exception
except ExceptionType:
    # Code to handle the exception
finally:
    # Code that will always be executed
```

## Example: Using the `finally` Block

```python
try:
    file = open("data.txt", "r")
    # Perform some operations on the file
except FileNotFoundError:
    print("Error: File not found.")
finally:
    file.close()
```

In this example, the file is opened in the `try` block, and if a `FileNotFoundError` occurs, the exception is handled in the `except` block. The `finally` block ensures that the file is always closed, regardless of whether an exception occurred or not.

## Conclusion

Exception handling is an essential part of writing reliable and robust Python code. By using `try`/`except` blocks, you can handle exceptions and gracefully handle errors in your programs.

For more information on exceptions and their types, refer to the official Python documentation: [Python Exceptions](https://docs.python.org/3/tutorial/errors.html)
